Workbook

Sheet Instructions
B2: Home Health Agency - Full Financial System (Daily Detail, Full Year)
B3: Sample Agency: Meridian Home Care Services | Illustrative Full-Year Demo (FY2025), Day-Level Detail
B5: PURPOSE
B6: A complete financial system for a mid-size home health agency, built at daily transaction granularity so any date range can be analyzed. All names, figures, and transactions are fictional/randomly generated for demonstration - they represent no real agency, client, or employee.
B10: TAB GUIDE
B11: Chart of Accounts | C11: Full account structure including balance sheet accounts, plus key rate/assumption cells.
B12: Caregiver Roster | C12: All 40 caregivers - role, pay type, rate, hire/term dates, certification tracking.
B13: Client Roster | C13: All 65 clients - payer, authorized units, service dates.
B14: Client Authorizations | C14: Medicaid/insurance authorization periods per client - flags expired/expiring authorizations.
B15: Caregiver Certifications | C15: Background check dates and certification expiry per caregiver - compliance tracking.
B16: Fixed Asset Register | C16: Vehicles, office/medical equipment - cost, useful life, monthly depreciation, net book value.
B17: Daily Visit Register | C17: Every single visit for the year (8,124 rows) - the source of truth for all revenue.
B18: Daily Payroll Register | C18: Every caregiver's pay every day (5,973 rows) - the source of truth for all labor cost.
B19: Missed Visits Log | C19: Uncovered/cancelled visits and the revenue lost - an operational KPI source.
B20: Payroll Summary | C20: Monthly payroll rollup from the Daily Payroll Register, with employer burden.
B21: Revenue by Payer | C21: Monthly revenue rollup from the Daily Visit Register, by payer.
B22: AR Aging | C22: Month-end receivable balance by payer, reflecting each payer's collection speed.
... B33: KPI Dashboard | C33: Profitability by caregiver and by client, utilization, turnover, missed-visit rate, and more.
B35: COLOR KEY
B36: Blue text | C36: Hardcoded input / source data.
B37: Black text | C37: Formula calculated from other cells.
B38: Green text | C38: Link pulling from another tab.
B39: Yellow fill | C39: Key assumption/rate, or a date-range input cell to edit.
B41: KEY DESIGN NOTE: DAILY DATA VOLUME
B42: The Daily Visit Register and Daily Payroll Register contain full day-level transaction detail (~14,000 rows combined) so any custom date range can be analyzed precisely. Monthly summary tabs (Payroll Summary, Revenue by Payer, AR Aging, Overhead, P&L) roll this up via formulas for readability and faster recalculation. The Custom Date-Range P&L tab queries the daily registers directly for any period you specify.

Sheet Chart of Accounts
B2: Chart of Accounts - Home Health Agency Structure
B3: Full structure including balance sheet accounts for the daily-detail financial system.
B5: Acct # | C5: Account Name | D5: Type | E5: Notes
B6: 1000 - ASSETS
B7: 1010 | C7: Cash - Operating Account | D7: Asset | E7: See Bank Reconciliation and Cash Flow tabs
B8: 1200 | C8: Accounts Receivable - Medicaid Waiver | D8: Asset | E8: See AR Aging tab
B9: 1210 | C9: Accounts Receivable - Private Pay | D9: Asset
B10: 1220 | C10: Accounts Receivable - Medicare | D10: Asset
B11: 1230 | C11: Accounts Receivable - Private Insurance | D11: Asset
B12: 1500 | C12: Fixed Assets - Vehicles | D12: Asset | E12: See Fixed Asset Register
B13: 1510 | C13: Fixed Assets - Office Equipment | D13: Asset
B14: 1520 | C14: Fixed Assets - Medical Equipment | D14: Asset
B15: 1590 | C15: Accumulated Depreciation | D15: Contra-Asset | E15: Reduces gross fixed assets to net book value
B16: 2000 - LIABILITIES
B17: 2100 | C17: Accrued Payroll Payable | D17: Liability | E17: Payroll earned but unpaid at period-end
B18: 2200 | C18: Payroll Taxes Payable | D18: Liability | E18: Employer + withheld employee taxes due
B19: 2500 | C19: Line of Credit Payable | D19: Liability | E19: See Line of Credit tab - revolving facility
B20: 3000 - EQUITY
B21: 3010 | C21: Owner's Capital Contribution | D21: Equity | E21: See Statement of Owner's Equity
B22: 3020 | C22: Owner's Draws | D22: Equity | E22: Distributions to owner, reduces equity
B23: 3030 | C23: Retained Earnings | D23: Equity | E23: Cumulative net income
B24: 4000 - REVENUE (by Payer)
B25: 4010 | C25: Revenue - Medicaid Waiver (Hourly) | D25: Income | E25: Billed at contracted hourly rate
B26: 4020 | C26: Revenue - Private Pay (Hourly) | D26: Income | E26: Fastest-collecting payer
B27: 4030 | C27: Revenue - Medicare Skilled (Per-Visit) | D27: Income | E27: Billed per visit/episode
B28: 4040 | C28: Revenue - Private Insurance (Per-Visit) | D28: Income | E28: Billed per payer fee schedule
B29: 4090 | C29: Contra - Claim Denials & Write-offs | D29: Contra-Income | E29: Netted against gross billed revenue
B30: 5000 - COST OF SERVICES (Direct Caregiver Labor)
B31: 5010 | C31: Caregiver Wages - Regular (Hourly) | D31: COGS
B32: 5020 | C32: Caregiver Wages - Overtime (Hourly) | D32: COGS | E32: 1.5x, weekly threshold basis
B33: 5030 | C33: Caregiver Pay - Per-Visit (LPN/RN/Therapy) | D33: COGS
B34: 5040 | C34: Mileage Reimbursement | D34: COGS | E34: IRS standard mileage rate
B35: 5050 | C35: Payroll Tax & Burden (Employer Share) | D35: COGS | E35: FICA, FUTA/SUTA, workers' comp, benefits
B36: 6000 - OPERATING EXPENSES (Overhead)
B37: 6010 | C37: Office Rent | D37: Opex
B38: 6020 | C38: Office Utilities | D38: Opex
B39: 6030 | C39: Admin Salaries (Office/Scheduling Staff) | D39: Opex
B40: 6040 | C40: Owner / Executive Compensation | D40: Opex
B41: 6050 | C41: Scheduling / EVV Software | D41: Opex | E41: Federally mandated for Medicaid personal care
B42: 6060 | C42: Accounting Software | D42: Opex
...

Sheet Caregiver Roster
B2: Caregiver Roster
B3: All caregivers for the demo year. Pay type and rate drive the Daily Payroll Register.
B5: Caregiver ID | C5: Name | D5: Role | E5: Pay Type | F5: Pay Rate | G5: Mileage Eligible | H5: Hire Date | I5: Term Date | J5: Status
B6: CG-001 | C6: Maria Garcia | D6: Personal Care Aide | E6: Hourly | F6: 14.56 | G6: Yes | H6: 45658 | I6: - | J6: Active
B7: CG-002 | C7: James Smith | D7: Home Health Aide | E7: Hourly | F7: 17.34 | G7: Yes | H7: 45658 | I7: - | J7: Active
B8: CG-003 | C8: Linda Johnson | D8: RN | E8: Per Visit | F8: 66.48 | G8: No | H8: 45658 | I8: - | J8: Active
B9: CG-004 | C9: Robert Williams | D9: Home Health Aide | E9: Hourly | F9: 16.05 | G9: Yes | H9: 45658 | I9: 45810 | J9: Terminated
B10: CG-005 | C10: Patricia Brown | D10: Home Health Aide | E10: Hourly | F10: 16 | G10: Yes | H10: 45658 | I10: - | J10: Active
B11: CG-006 | C11: John Jones | D11: Personal Care Aide | E11: Hourly | F11: 15.05 | G11: Yes | H11: 45658 | I11: - | J11: Active
B12: CG-007 | C12: Barbara Miller | D12: LPN | E12: Per Visit | F12: 48.09 | G12: No | H12: 45770 | I12: - | J12: Active
B13: CG-008 | C13: Michael Davis | D13: Personal Care Aide | E13: Hourly | F13: 15.19 | G13: Yes | H13: 45658 | I13: - | J13: Active
B14: CG-009 | C14: Jennifer Rodriguez | D14: LPN | E14: Per Visit | F14: 49.43 | G14: No | H14: 45658 | I14: - | J14: Active
B15: CG-010 | C15: David Martinez | D15: Home Health Aide | E15: Hourly | F15: 16.36 | G15: Yes | H15: 45658 | I15: - | J15: Active
B16: CG-011 | C16: Susan Hernandez | D16: Home Health Aide | E16: Hourly | F16: 16.65 | G16: Yes | H16: 45658 | I16: 45896 | J16: Terminated
B17: CG-012 | C17: Richard Lopez | D17: PT/OT Therapist | E17: Per Visit | F17: 73.58 | G17: No | H17: 45658 | I17: - | J17: Active
B18: CG-013 | C18: Jessica Wilson | D18: Personal Care Aide | E18: Hourly | F18: 16.71 | G18: Yes | H18: 45658 | I18: 45837 | J18: Terminated
B19: CG-014 | C19: Charles Anderson | D19: Home Health Aide | E19: Hourly | F19: 15.67 | G19: Yes | H19: 45658 | I19: - | J19: Active
B20: CG-015 | C20: Karen Thomas | D20: LPN | E20: Per Visit | F20: 61.79 | G20: No | H20: 45866 | I20: - | J20: Active
B21: CG-016 | C21: Joseph Taylor | D21: Home Health Aide | E21: Hourly | F21: 16.19 | G21: Yes | H21: 45658 | I21: - | J21: Active
B22: CG-017 | C22: Nancy Moore | D22: Home Health Aide | E22: Hourly | F22: 16.43 | G22: Yes | H22: 45658 | I22: - | J22: Active
B23: CG-018 | C23: Thomas Jackson | D23: Home Health Aide | E23: Hourly | F23: 17.84 | G23: Yes | H23: 45658 | I23: - | J23: Active
B24: CG-019 | C24: Betty Martin | D24: Personal Care Aide | E24: Hourly | F24: 14.93 | G24: Yes | H24: 45658 | I24: - | J24: Active
B25: CG-020 | C25: Christopher Lee | D25: Home Health Aide | E25: Hourly | F25: 16.45 | G25: Yes | H25: 46012 | I25: - | J25: Active
B26: CG-021 | C26: Sandra Perez | D26: LPN | E26: Per Visit | F26: 51.07 | G26: No | H26: 45658 | I26: - | J26: Active
B27: CG-022 | C27: Daniel Thompson | D27: LPN | E27: Per Visit | F27: 48.78 | G27: No | H27: 45803 | I27: - | J27: Active
B28: CG-023 | C28: Ashley White | D28: Home Health Aide | E28: Hourly | F28: 16.17 | G28: Yes | H28: 45658 | I28: - | J28: Active
B29: CG-024 | C29: Paul Harris | D29: PT/OT Therapist | E29: Per Visit | F29: 89.53 | G29: No | H29: 45658 | I29: - | J29: Active
B30: CG-025 | C30: Kimberly Sanchez | D30: Personal Care Aide | E30: Hourly | F30: 15.49 | G30: Yes | H30: 45915 | I30: - | J30: Active
... B42: CG-037 | C42: Melissa Nguyen | D42: RN | E42: Per Visit | F42: 79.8 | G42: No | H42: 45658 | I42: - | J42: Active
B43: CG-038 | C43: Ronald Hill | D43: Personal Care Aide | E43: Hourly | F43: 16.02 | G43: Yes | H43: 45658 | I43: 45801 | J43: Terminated
B44: CG-039 | C44: Deborah Flores | D44: LPN | E44: Per Visit | F44: 55.55 | G44: No | H44: 45733 | I44: - | J44: Active
B45: CG-040 | C45: Anthony Green | D45: RN | E45: Per Visit | F45: 75.18 | G45: No | H45: 45658 | I45: 45903 | J45: Terminated
B47: Total Caregivers: 40
B48: Active at Year-End: | C48: =COUNTIF(J6:J45,"Active") -> 35
B49: Terminated During Year (Turnover Count): | C49: =COUNTIF(J6:J45,"Terminated") -> 5
B50: Annualized Turnover Rate (Terminated ÷ Avg Headcount): | C50: =C49/((COUNTA(B6:B45)+C48)/2) -> 0.13333333

Sheet Client Roster
B2: Client Roster
B3: All clients for the demo year, by payer type, with authorized vs. actual weekly units.
B5: Client ID | C5: Client (Household) | D5: Payer | E5: Weekly Units (Actual) | F5: Weekly Units (Authorized) | G5: Unit Type | H5: Start Date | I5: End Date | J5: Status
B6: CL-001 | C6: Adams Household | D6: Medicare (Skilled) | E6: 3 | F6: 3.6 | G6: Visits/wk | H6: 45658 | I6: 45891 | J6: Discharged
B7: CL-002 | C7: Baker Household | D7: Medicare (Skilled) | E7: 1 | F7: 1.3 | G7: Visits/wk | H7: 45995 | I7: - | J7: Active
B8: CL-003 | C8: Carter Household | D8: Medicare (Skilled) | E8: 1 | F8: 1.2 | G8: Visits/wk | H8: 45658 | I8: 45820 | J8: Discharged
B9: CL-004 | C9: Diaz Household | D9: Private Pay | E9: 28 | F9: 30 | G9: Hours/wk | H9: 45658 | I9: - | J9: Active
B10: CL-005 | C10: Evans Household | D10: Medicaid Waiver | E10: 14 | F10: 16 | G10: Hours/wk | H10: 45658 | I10: - | J10: Active
B11: CL-006 | C11: Fisher Household | D11: Medicare (Skilled) | E11: 2 | F11: 2.5 | G11: Visits/wk | H11: 45903 | I11: - | J11: Active
B12: CL-007 | C12: Gray Household | D12: Medicaid Waiver | E12: 12 | F12: 14.5 | G12: Hours/wk | H12: 45873 | I12: - | J12: Active
B13: CL-008 | C13: Hughes Household | D13: Private Pay | E13: 6 | F13: 7.1 | G13: Hours/wk | H13: 45658 | I13: - | J13: Active
B14: CL-009 | C14: Irwin Household | D14: Medicaid Waiver | E14: 6 | F14: 7.5 | G14: Hours/wk | H14: 45958 | I14: - | J14: Active
B15: CL-010 | C15: Jenkins Household | D15: Medicare (Skilled) | E15: 2 | F15: 2.3 | G15: Visits/wk | H15: 45658 | I15: - | J15: Active
B16: CL-011 | C16: Kelly Household | D16: Medicaid Waiver | E16: 8 | F16: 9.8 | G16: Hours/wk | H16: 45936 | I16: - | J16: Active
B17: CL-012 | C17: Lambert Household | D17: Medicaid Waiver | E17: 12 | F17: 12.6 | G17: Hours/wk | H17: 45658 | I17: - | J17: Active
B18: CL-013 | C18: Morgan Household | D18: Medicare (Skilled) | E18: 3 | F18: 3.6 | G18: Visits/wk | H18: 45740 | I18: - | J18: Active
B19: CL-014 | C19: Nash Household | D19: Private Insurance | E19: 3 | F19: 3.4 | G19: Visits/wk | H19: 45658 | I19: - | J19: Active
B20: CL-015 | C20: Owens Household | D20: Medicaid Waiver | E20: 6 | F20: 7 | G20: Hours/wk | H20: 45658 | I20: - | J20: Active
... B29: CL-024 | C29: Xu Household | D29: Private Pay | E29: 20 | F29: 22.3 | G29: Hours/wk | H29: 45658 | I29: - | J29: Active
B30: CL-025 | C30: Yates Household | D30: Private Pay | E30: 8 | F30: 9.5 | G30: Hours/wk | H30: 45658 | I30: 45991 | J30: Discharged
B31: CL-026 | C31: Zimmerman Household | D31: Medicaid Waiver | E31: 10 | F31: 12.4 | G31: Hours/wk | H31: 45931 | I31: - | J31: Active
B32: CL-027 | C32: Bell Household | D32: Medicaid Waiver | E32: 12 | F32: 14.1 | G32: Hours/wk | H32: 45658 | I32: - | J32: Active
B33: CL-028 | C33: Cole Household | D33: Medicaid Waiver | E33: 6 | F33: 6.4 | G33: Hours/wk | H33: 45658 | I33: 45889 | J33: Discharged
B34: CL-029 | C34: Dunn Household | D34: Medicaid Waiver | E34: 10 | F34: 10.8 | G34: Hours/wk | H34: 45658 | I34: - | J34: Active
B35: CL-030 | C35: Ellis Household | D35: Private Pay | E35: 6 | F35: 7.4 | G35: Hours/wk | H35: 45658 | I35: - | J35: Active
B36: CL-031 | C36: Ford Household | D36: Medicaid Waiver | E36: 8 | F36: 9.1 | G36: Hours/wk | H36: 45658 | I36: - | J36: Active
B37: CL-032 | C37: Grant Household | D37: Private Insurance | E37: 2 | F37: 2.6 | G37: Visits/wk | H37: 46012 | I37: - | J37: Active
B38: CL-033 | C38: Hart Household | D38: Medicaid Waiver | E38: 14 | F38: 14.7 | G38: Hours/wk | H38: 45848 | I38: 45983 | J38: Discharged
B39: CL-034 | C39: Ingram Household | D39: Medicaid Waiver | E39: 20 | F39: 21.4 | G39: Hours/wk | H39: 45909 | I39: - | J39: Active
B40: CL-035 | C40: Jordan Household | D40: Medicaid Waiver | E40: 6 | F40: 7.4 | G40: Hours/wk | H40: 45752 | I40: - | J40: Active
B41: CL-036 | C41: Knight Household | D41: Medicaid Waiver | E41: 10 | F41: 11.1 | G41: Hours/wk | H41: 45658 | I41: - | J41: Active
B42: CL-037 | C42: Lane Household | D42: Medicaid Waiver | E42: 10 | F42: 10.9 | G42: Hours/wk | H42: 45658 | I42: - | J42: Active
B43: CL-038 | C43: Mills Household | D43: Medicaid Waiver | E43: 10 | F43: 11.5 | G43: Hours/wk | H43: 45658 | I43: - | J43: Active
B44: CL-039 | C44: Norris Household | D44: Private Pay | E44: 28 | F44: 29.7 | G44: Hours/wk | H44: 45658 | I44: - | J44: Active
B45: CL-040 | C45: Ortiz Household | D45: Medicare (Skilled) | E45: 2 | F45: 2.2 | G45: Visits/wk | H45: 45658 | I45: - | J45: Active
B46: CL-041 | C46: Pratt Household | D46: Private Pay | E46: 8 | F46: 9.4 | G46: Hours/wk | H46: 45658 | I46: - | J46: Active
B47: CL-042 | C47: Quincy Household | D47: Medicaid Waiver | E47: 20 | F47: 22.8 | G47: Hours/wk | H47: 45765 | I47: - | J47: Active
B48: CL-043 | C48: Ross Household | D48: Private Pay | E48: 6 | F48: 6.4 | G48: Hours/wk | H48: 45984 | I48: - | J48: Active
B49: CL-044 | C49: Shaw Household | D49: Private Insurance | E49: 2 | F49: 2.5 | G49: Visits/wk | H49: 45857 | I49: - | J49: Active
B50: CL-045 | C50: Tate Household | D50: Medicaid Waiver | E50: 14 | F50: 15.1 | G50: Hours/wk | H50: 45658 | I50: - | J50: Active
...

Sheet Client Authorizations
B2: Client Authorization Register
B3: Medicaid/insurance authorization periods. Billing against an expired authorization is a real audit exposure.
B5: Client ID | C5: Client | D5: Payer | E5: Auth Start | F5: Auth End | G5: Days Until Expiry (as of 12/31) | H5: Status | I5: Action Needed
B6: CL-001 | C6: Adams Household | D6: Medicare (Skilled) | E6: 45658 | F6: 45866 | G6: =F6-DATE(2025,12,31) -> -156 | H6: =IF(G6<0,"EXPIRED",IF(G6<=30,"Expiring Soon","Current")) -> EXPIRED | I6: =IF(H6="EXPIRED","Renew immediately - billing exposure",IF(H6="Expiring Soon","Initiate renewal","None")) -> Renew immediately - billing exposure
B7: CL-002 | C7: Baker Household | D7: Medicare (Skilled) | E7: 45995 | F7: 46201 | G7: =F7-DATE(2025,12,31) -> 179 | H7: =IF(G7<0,"EXPIRED",IF(G7<=30,"Expiring Soon","Current")) -> Current | I7: =IF(H7="EXPIRED","Renew immediately - billing exposure",IF(H7="Expiring Soon","Initiate renewal","None")) -> None
B8: CL-003 | C8: Carter Household | D8: Medicare (Skilled) | E8: 45658 | F8: 45866 | G8: =F8-DATE(2025,12,31) -> -156 | H8: =IF(G8<0,"EXPIRED",IF(G8<=30,"Expiring Soon","Current")) -> EXPIRED | I8: =IF(H8="EXPIRED","Renew immediately - billing exposure",IF(H8="Expiring Soon","Initiate renewal","None")) -> Renew immediately - billing exposure
B9: CL-004 | C9: Diaz Household | D9: Private Pay | E9: 45658 | F9: 45866 | G9: =F9-DATE(2025,12,31) -> -156 | H9: =IF(G9<0,"EXPIRED",IF(G9<=30,"Expiring Soon","Current")) -> EXPIRED | I9: =IF(H9="EXPIRED","Renew immediately - billing exposure",IF(H9="Expiring Soon","Initiate renewal","None")) -> Renew immediately - billing exposure
B10: CL-005 | C10: Evans Household | D10: Medicaid Waiver | E10: 45658 | F10: 45866 | G10: =F10-DATE(2025,12,31) -> -156 | H10: =IF(G10<0,"EXPIRED",IF(G10<=30,"Expiring Soon","Current")) -> EXPIRED | I10: =IF(H10="EXPIRED","Renew immediately - billing exposure",IF(H10="Expiring Soon","Initiate renewal","None")) -> Renew immediately - billing exposure
B11: CL-006 | C11: Fisher Household | D11: Medicare (Skilled) | E11: 45903 | F11: 46109 | G11: =F11-DATE(2025,12,31) -> 87 | H11: =IF(G11<0,"EXPIRED",IF(G11<=30,"Expiring Soon","Current")) -> Current | I11: =IF(H11="EXPIRED","Renew immediately - billing exposure",IF(H11="Expiring Soon","Initiate renewal","None")) -> None
B12: CL-007 | C12: Gray Household | D12: Medicaid Waiver | E12: 45873 | F12: 46081 | G12: =F12-DATE(2025,12,31) -> 59 | H12: =IF(G12<0,"EXPIRED",IF(G12<=30,"Expiring Soon","Current")) -> Current | I12: =IF(H12="EXPIRED","Renew immediately - billing exposure",IF(H12="Expiring Soon","Initiate renewal","None")) -> None
B13: CL-008 | C13: Hughes Household | D13: Private Pay | E13: 45658 | F13: 45866 | G13: =F13-DATE(2025,12,31) -> -156 | H13: =IF(G13<0,"EXPIRED",IF(G13<=30,"Expiring Soon","Current")) -> EXPIRED | I13: =IF(H13="EXPIRED","Renew immediately - billing exposure",IF(H13="Expiring Soon","Initiate renewal","None")) -> Renew immediately - billing exposure
B14: CL-009 | C14: Irwin Household | D14: Medicaid Waiver | E14: 45958 | F14: 46140 | G14: =F14-DATE(2025,12,31) -> 118 | H14: =IF(G14<0,"EXPIRED",IF(G14<=30,"Expiring Soon","Current")) -> Current | I14: =IF(H14="EXPIRED","Renew immediately - billing exposure",IF(H14="Expiring Soon","Initiate renewal","None")) -> None
B15: CL-010 | C15: Jenkins Household | D15: Medicare (Skilled) | E15: 45658 | F15: 45866 | G15: =F15-DATE(2025,12,31) -> -156 | H15: =IF(G15<0,"EXPIRED",IF(G15<=30,"Expiring Soon","Current")) -> EXPIRED | I15: =IF(H15="EXPIRED","Renew immediately - billing exposure",IF(H15="Expiring Soon","Initiate renewal","None")) -> Renew immediately - billing exposure
B16: CL-011 | C16: Kelly Household | D16: Medicaid Waiver | E16: 45936 | F16: 46140 | G16: =F16-DATE(2025,12,31) -> 118 | H16: =IF(G16<0,"EXPIRED",IF(G16<=30,"Expiring Soon","Current")) -> Current | I16: =IF(H16="EXPIRED","Renew immediately - billing exposure",IF(H16="Expiring Soon","Initiate renewal","None")) -> None
B17: CL-012 | C17: Lambert Household | D17: Medicaid Waiver | E17: 45658 | F17: 45866 | G17: =F17-DATE(2025,12,31) -> -156 | H17: =IF(G17<0,"EXPIRED",IF(G17<=30,"Expiring Soon","Current")) -> EXPIRED | I17: =IF(H17="EXPIRED","Renew immediately - billing exposure",IF(H17="Expiring Soon","Initiate renewal","None")) -> Renew immediately - billing exposure
... B70: CL-065 | C70: Reyes Household | D70: Medicaid Waiver | E70: 45658 | F70: 45866 | G70: =F70-DATE(2025,12,31) -> -156 | H70: =IF(G70<0,"EXPIRED",IF(G70<=30,"Expiring Soon","Current")) -> EXPIRED | I70: =IF(H70="EXPIRED","Renew immediately - billing exposure",IF(H70="Expiring Soon","Initiate renewal","None")) -> Renew immediately - billing exposure
B72: Authorizations Expired or Expiring Within 30 Days: | C72: =COUNTIF(H6:H70,"EXPIRED")+COUNTIF(H6:H70,"Expiring Soon") -> 52

Sheet Caregiver Certifications
B2: Caregiver Certification & Background Check Register
B3: Background check and certification renewal tracking - lapses are a compliance/liability exposure.
B5: Caregiver ID | C5: Name | D5: Background Check Date | E5: Cert Expiry Date | F5: Days Until Expiry (as of 12/31) | G5: Status | H5: Action Needed
B6: CG-001 | C6: Maria Garcia | D6: 45658 | E6: 46023 | F6: =E6-DATE(2025,12,31) -> 1 | G6: =IF(F6<0,"EXPIRED",IF(F6<=60,"Expiring Soon","Current")) -> Expiring Soon | H6: =IF(G6="EXPIRED","Cannot bill for this caregiver - renew now",IF(G6="Expiring Soon","Schedule renewal","None")) -> Schedule renewal
B7: CG-002 | C7: James Smith | D7: 45658 | E7: 46023 | F7: =E7-DATE(2025,12,31) -> 1 | G7: =IF(F7<0,"EXPIRED",IF(F7<=60,"Expiring Soon","Current")) -> Expiring Soon | H7: =IF(G7="EXPIRED","Cannot bill for this caregiver - renew now",IF(G7="Expiring Soon","Schedule renewal","None")) -> Schedule renewal
B8: CG-003 | C8: Linda Johnson | D8: 45658 | E8: 46023 | F8: =E8-DATE(2025,12,31) -> 1 | G8: =IF(F8<0,"EXPIRED",IF(F8<=60,"Expiring Soon","Current")) -> Expiring Soon | H8: =IF(G8="EXPIRED","Cannot bill for this caregiver - renew now",IF(G8="Expiring Soon","Schedule renewal","None")) -> Schedule renewal
B9: CG-004 | C9: Robert Williams | D9: 45658 | E9: 46023 | F9: =E9-DATE(2025,12,31) -> 1 | G9: =IF(F9<0,"EXPIRED",IF(F9<=60,"Expiring Soon","Current")) -> Expiring Soon | H9: =IF(G9="EXPIRED","Cannot bill for this caregiver - renew now",IF(G9="Expiring Soon","Schedule renewal","None")) -> Schedule renewal
B10: CG-005 | C10: Patricia Brown | D10: 45658 | E10: 46023 | F10: =E10-DATE(2025,12,31) -> 1 | G10: =IF(F10<0,"EXPIRED",IF(F10<=60,"Expiring Soon","Current")) -> Expiring Soon | H10: =IF(G10="EXPIRED","Cannot bill for this caregiver - renew now",IF(G10="Expiring Soon","Schedule renewal","None")) -> Schedule renewal
B11: CG-006 | C11: John Jones | D11: 45658 | E11: 46023 | F11: =E11-DATE(2025,12,31) -> 1 | G11: =IF(F11<0,"EXPIRED",IF(F11<=60,"Expiring Soon","Current")) -> Expiring Soon | H11: =IF(G11="EXPIRED","Cannot bill for this caregiver - renew now",IF(G11="Expiring Soon","Schedule renewal","None")) -> Schedule renewal
B12: CG-007 | C12: Barbara Miller | D12: 45770 | E12: 46135 | F12: =E12-DATE(2025,12,31) -> 113 | G12: =IF(F12<0,"EXPIRED",IF(F12<=60,"Expiring Soon","Current")) -> Current | H12: =IF(G12="EXPIRED","Cannot bill for this caregiver - renew now",IF(G12="Expiring Soon","Schedule renewal","None")) -> None
B13: CG-008 | C13: Michael Davis | D13: 45658 | E13: 46023 | F13: =E13-DATE(2025,12,31) -> 1 | G13: =IF(F13<0,"EXPIRED",IF(F13<=60,"Expiring Soon","Current")) -> Expiring Soon | H13: =IF(G13="EXPIRED","Cannot bill for this caregiver - renew now",IF(G13="Expiring Soon","Schedule renewal","None")) -> Schedule renewal
B14: CG-009 | C14: Jennifer Rodriguez | D14: 45658 | E14: 46023 | F14: =E14-DATE(2025,12,31) -> 1 | G14: =IF(F14<0,"EXPIRED",IF(F14<=60,"Expiring Soon","Current")) -> Expiring Soon | H14: =IF(G14="EXPIRED","Cannot bill for this caregiver - renew now",IF(G14="Expiring Soon","Schedule renewal","None")) -> Schedule renewal
B15: CG-010 | C15: David Martinez | D15: 45658 | E15: 46023 | F15: =E15-DATE(2025,12,31) -> 1 | G15: =IF(F15<0,"EXPIRED",IF(F15<=60,"Expiring Soon","Current")) -> Expiring Soon | H15: =IF(G15="EXPIRED","Cannot bill for this caregiver - renew now",IF(G15="Expiring Soon","Schedule renewal","None")) -> Schedule renewal
B16: CG-011 | C16: Susan Hernandez | D16: 45658 | E16: 46023 | F16: =E16-DATE(2025,12,31) -> 1 | G16: =IF(F16<0,"EXPIRED",IF(F16<=60,"Expiring Soon","Current")) -> Expiring Soon | H16: =IF(G16="EXPIRED","Cannot bill for this caregiver - renew now",IF(G16="Expiring Soon","Schedule renewal","None")) -> Schedule renewal
B17: CG-012 | C17: Richard Lopez | D17: 45658 | E17: 46023 | F17: =E17-DATE(2025,12,31) -> 1 | G17: =IF(F17<0,"EXPIRED",IF(F17<=60,"Expiring Soon","Current")) -> Expiring Soon | H17: =IF(G17="EXPIRED","Cannot bill for this caregiver - renew now",IF(G17="Expiring Soon","Schedule renewal","None")) -> Schedule renewal
... B45: CG-040 | C45: Anthony Green | D45: 45658 | E45: 46023 | F45: =E45-DATE(2025,12,31) -> 1 | G45: =IF(F45<0,"EXPIRED",IF(F45<=60,"Expiring Soon","Current")) -> Expiring Soon | H45: =IF(G45="EXPIRED","Cannot bill for this caregiver - renew now",IF(G45="Expiring Soon","Schedule renewal","None")) -> Schedule renewal
B47: Certifications Expired or Expiring Within 60 Days: | C47: =COUNTIF(G6:G45,"EXPIRED")+COUNTIF(G6:G45,"Expiring Soon") -> 28

Sheet Fixed Asset Register
B2: Fixed Asset Register
B3: Vehicles and equipment, with straight-line monthly depreciation and net book value as of year-end.
B5: Asset ID | C5: Description | D5: Category | E5: Acquisition Date | F5: Cost | G5: Useful Life (Yrs) | H5: Salvage Value | I5: Monthly Depreciation | J5: Months Depreciated (FY) | K5: Accum. Depreciation (FY) | L5: Net Book Value (12/31)
B6: FA-001 | C6: 2023 Toyota Sienna (Agency Vehicle - Client Transport) | D6: Vehicle | E6: 45659 | F6: 28500 | G6: 5 | H6: 4000 | I6: =(F6-H6)/(G6*12) -> 408.33333 | J6: =MIN(12-MONTH(E6)+1,G6*12) -> 12 | K6: =I6*J6 -> 4900 | L6: =F6-K6 -> 23600
B7: FA-002 | C7: 2022 Honda CR-V (Agency Vehicle - Supervisor Use) | D7: Vehicle | E7: 45659 | F7: 22000 | G7: 5 | H7: 3000 | I7: =(F7-H7)/(G7*12) -> 316.66667 | J7: =MIN(12-MONTH(E7)+1,G7*12) -> 12 | K7: =I7*J7 -> 3800 | L7: =F7-K7 -> 18200
B8: FA-003 | C8: Office Computers and Workstations (5 units) | D8: Office Equipment | E8: 45662 | F8: 6500 | G8: 3 | H8: 0 | I8: =(F8-H8)/(G8*12) -> 180.55556 | J8: =MIN(12-MONTH(E8)+1,G8*12) -> 12 | K8: =I8*J8 -> 2166.6667 | L8: =F8-K8 -> 4333.3333
B9: FA-004 | C9: Office Furniture (desks, chairs, filing) | D9: Office Equipment | E9: 45662 | F9: 4200 | G9: 7 | H9: 0 | I9: =(F9-H9)/(G9*12) -> 50 | J9: =MIN(12-MONTH(E9)+1,G9*12) -> 12 | K9: =I9*J9 -> 600 | L9: =F9-K9 -> 3600
B10: FA-005 | C10: Medical Equipment (BP cuffs, scales, gait belts, pulse-ox - shared pool) | D10: Medical Equipment | E10: 45667 | F10: 3200 | G10: 4 | H10: 0 | I10: =(F10-H10)/(G10*12) -> 66.666667 | J10: =MIN(12-MONTH(E10)+1,G10*12) -> 12 | K10: =I10*J10 -> 800 | L10: =F10-K10 -> 2400
B11: FA-006 | C11: EVV / Scheduling System - Hardware and Setup (tablets for field staff) | D11: Office Equipment | E11: 45689 | F11: 2800 | G11: 3 | H11: 0 | I11: =(F11-H11)/(G11*12) -> 77.777778 | J11: =MIN(12-MONTH(E11)+1,G11*12) -> 11 | K11: =I11*J11 -> 855.55556 | L11: =F11-K11 -> 1944.4444
B12: FA-007 | C12: 2024 Ford Transit Connect (Agency Vehicle - Added for Growth) | D12: Vehicle | E12: 45884 | F12: 26500 | G12: 5 | H12: 3500 | I12: =(F12-H12)/(G12*12) -> 383.33333 | J12: =MIN(12-MONTH(E12)+1,G12*12) -> 5 | K12: =I12*J12 -> 1916.6667 | L12: =F12-K12 -> 24583.333
B13: FA-008 | C13: 2021 Honda Odyssey (Agency Vehicle - Added for Q4 Growth) | D13: Vehicle | E13: 45931 | F13: 21000 | G13: 5 | H13: 3000 | I13: =(F13-H13)/(G13*12) -> 300 | J13: =MIN(12-MONTH(E13)+1,G13*12) -> 3 | K13: =I13*J13 -> 900 | L13: =F13-K13 -> 20100
B14: FA-009 | C14: Additional Medical Equipment (wheelchairs, hospital bed rails - 2nd batch) | D14: Medical Equipment | E14: 45778 | F14: 2400 | G14: 4 | H14: 0 | I14: =(F14-H14)/(G14*12) -> 50 | J14: =MIN(12-MONTH(E14)+1,G14*12) -> 8 | K14: =I14*J14 -> 400 | L14: =F14-K14 -> 2000
B15: FA-010 | C15: Server / Network Infrastructure Upgrade | D15: Office Equipment | E15: 45731 | F15: 3600 | G15: 3 | H15: 0 | I15: =(F15-H15)/(G15*12) -> 100 | J15: =MIN(12-MONTH(E15)+1,G15*12) -> 10 | K15: =I15*J15 -> 1000 | L15: =F15-K15 -> 2600
B16: FA-011 | C16: Office Security System (cameras, access control) | D16: Office Equipment | E16: 45748 | F16: 1850 | G16: 5 | H16: 0 | I16: =(F16-H16)/(G16*12) -> 30.833333 | J16: =MIN(12-MONTH(E16)+1,G16*12) -> 9 | K16: =I16*J16 -> 277.5 | L16: =F16-K16 -> 1572.5
B17: FA-012 | C17: Leasehold Improvements (office buildout, ADA ramp) | D17: Leasehold Improvements | E17: 45672 | F17: 8500 | G17: 7 | H17: 0 | I17: =(F17-H17)/(G17*12) -> 101.19048 | J17: =MIN(12-MONTH(E17)+1,G17*12) -> 12 | K17: =I17*J17 -> 1214.2857 | L17: =F17-K17 -> 7285.7143
B19: TOTALS | F19: =SUM(F6:F17) -> 131050 | K19: =SUM(K6:K17) -> 18830.675 | L19: =SUM(L6:L17) -> 112219.33
B21: MONTHLY DEPRECIATION SCHEDULE
C22: Jan-2025 | D22: Feb-2025 | E22: Mar-2025 | F22: Apr-2025 | G22: May-2025 | H22: Jun-2025 | I22: Jul-2025 | J22: Aug-2025 | K22: Sep-2025 | L22: Oct-2025 | M22: Nov-2025 | N22: Dec-2025
B23: Total Monthly Depreciation | C23: 1123.42 | D23: 1201.2 | E23: 1301.2 | F23: 1332.03 | G23: 1382.03 | H23: 1382.03 | I23: 1382.03 | J23: 1765.36 | K23: 1765.36 | L23: 2065.36 | M23: 2065.36 | N23: 2065.36
B25: OTHER ASSETS (Non-Depreciable)
B26: Item | C26: Type | D26: Date | E26: Amount | F26: Notes
B27: Office Lease Security Deposit | C27: Security Deposit | D27: 45658 | E27: 4400 | F27: Refundable at end of lease term
B28: General Liability Insurance - Annual Premium (Prepaid) | C28: Prepaid Expense | D28: 45658 | E28: 11400 | F28: 12-month policy, amortized monthly to Insurance expense
B30: TOTAL OTHER ASSETS | E30: =SUM(E27:E28) -> 15800

Sheet Daily Visit Register
B2: Daily Visit Register - Every Visit, Full Year
B3: 8,124 visit records. Source of truth for all revenue calculations across the workbook.
B5: Visit ID | C5: Date | D5: Client ID | E5: Payer | F5: Caregiver ID | G5: Unit Type | H5: Gross Units | I5: Denied Units | J5: Net Units | K5: Rate | L5: Net Revenue | M5: Attributed Labor Cost
B6: V-000001 | C6: 45658 | D6: CL-001 | E6: Medicare (Skilled) | F6: CG-003 | G6: Visits | H6: 0.91 | I6: 0 | J6: =H6-I6 -> 0.91 | K6: 165 | L6: =J6*K6 -> 150.15 | M6: =H6*66.48*(1+'Chart of Accounts'!$E$67) -> 69.268836
B7: V-000002 | C7: 45658 | D7: CL-003 | E7: Medicare (Skilled) | F7: CG-021 | G7: Visits | H7: 0.99 | I7: 0 | J7: =H7-I7 -> 0.99 | K7: 165 | L7: =J7*K7 -> 163.35 | M7: =H7*51.07*(1+'Chart of Accounts'!$E$67) -> 57.890399
B8: V-000003 | C8: 45658 | D8: CL-004 | E8: Private Pay | F8: CG-004 | G8: Hours | H8: 4.39 | I8: 0 | J8: =H8-I8 -> 4.39 | K8: 34 | L8: =J8*K8 -> 149.26 | M8: =H8*16.05*(1+'Chart of Accounts'!$E$67) -> 80.676128
B9: V-000004 | C9: 45658 | D9: CL-005 | E9: Medicaid Waiver | F9: CG-005 | G9: Hours | H9: 5.03 | I9: 0 | J9: =H9-I9 -> 5.03 | K9: 26.5 | L9: =J9*K9 -> 133.295 | M9: =H9*16*(1+'Chart of Accounts'!$E$67) -> 92.1496
B10: V-000005 | C10: 45658 | D10: CL-012 | E10: Medicaid Waiver | F10: CG-010 | G10: Hours | H10: 4 | I10: 0 | J10: =H10-I10 -> 4 | K10: 26.5 | L10: =J10*K10 -> 106 | M10: =H10*16.36*(1+'Chart of Accounts'!$E$67) -> 74.9288
B11: V-000006 | C11: 45658 | D11: CL-014 | E11: Private Insurance | F11: CG-033 | G11: Visits | H11: 1.08 | I11: 0 | J11: =H11-I11 -> 1.08 | K11: 135 | L11: =J11*K11 -> 145.8 | M11: =H11*57.54*(1+'Chart of Accounts'!$E$67) -> 71.153964
B12: V-000007 | C12: 45658 | D12: CL-016 | E12: Private Pay | F12: CG-002 | G12: Hours | H12: 3.81 | I12: 0 | J12: =H12-I12 -> 3.81 | K12: 34 | L12: =J12*K12 -> 129.54 | M12: =H12*17.34*(1+'Chart of Accounts'!$E$67) -> 75.644883
B13: V-000008 | C13: 45658 | D13: CL-020 | E13: Medicaid Waiver | F13: CG-016 | G13: Hours | H13: 4.21 | I13: 0 | J13: =H13-I13 -> 4.21 | K13: 26.5 | L13: =J13*K13 -> 111.565 | M13: =H13*16.19*(1+'Chart of Accounts'!$E$67) -> 78.043086
B14: V-000009 | C14: 45658 | D14: CL-024 | E14: Private Pay | F14: CG-017 | G14: Hours | H14: 3.82 | I14: 0 | J14: =H14-I14 -> 3.82 | K14: 34 | L14: =J14*K14 -> 129.88 | M14: =H14*16.43*(1+'Chart of Accounts'!$E$67) -> 71.863177
B15: V-000010 | C15: 45658 | D15: CL-027 | E15: Medicaid Waiver | F15: CG-001 | G15: Hours | H15: 3.82 | I15: 0 | J15: =H15-I15 -> 3.82 | K15: 26.5 | L15: =J15*K15 -> 101.23 | M15: =H15*14.56*(1+'Chart of Accounts'!$E$67) -> 63.683984
B16: V-000011 | C16: 45658 | D16: CL-029 | E16: Medicaid Waiver | F16: CG-028 | G16: Hours | H16: 3.09 | I16: 0 | J16: =H16-I16 -> 3.09 | K16: 26.5 | L16: =J16*K16 -> 81.885 | M16: =H16*17.99*(1+'Chart of Accounts'!$E$67) -> 63.649519
B17: V-000012 | C17: 45658 | D17: CL-036 | E17: Medicaid Waiver | F17: CG-034 | G17: Hours | H17: 3.47 | I17: 0 | J17: =H17-I17 -> 3.47 | K17: 26.5 | L17: =J17*K17 -> 91.955 | M17: =H17*17.1*(1+'Chart of Accounts'!$E$67) -> 67.940865
B18: V-000013 | C18: 45658 | D18: CL-037 | E18: Medicaid Waiver | F18: CG-008 | G18: Hours | H18: 3.36 | I18: 0 | J18: =H18-I18 -> 3.36 | K18: 26.5 | L18: =J18*K18 -> 89.04 | M18: =H18*15.19*(1+'Chart of Accounts'!$E$67) -> 58.438968
B19: V-000014 | C19: 45658 | D19: CL-038 | E19: Medicaid Waiver | F19: CG-011 | G19: Hours | H19: 3.28 | I19: 0 | J19: =H19-I19 -> 3.28 | K19: 26.5 | L19: =J19*K19 -> 86.92 | M19: =H19*16.65*(1+'Chart of Accounts'!$E$67) -> 62.53074
B20: V-000015 | C20: 45658 | D20: CL-039 | E20: Private Pay | F20: CG-013 | G20: Hours | H20: 4.16 | I20: 0 | J20: =H20-I20 -> 4.16 | K20: 34 | L20: =J20*K20 -> 141.44 | M20: =H20*16.71*(1+'Chart of Accounts'!$E$67) -> 79.593072
B21: V-000016 | C21: 45658 | D21: CL-049 | E21: Private Pay | F21: CG-019 | G21: Hours | H21: 4.48 | I21: 0 | J21: =H21-I21 -> 4.48 | K21: 34 | L21: =J21*K21 -> 152.32 | M21: =H21*14.93*(1+'Chart of Accounts'!$E$67) -> 76.584928
B22: V-000017 | C22: 45658 | D22: CL-054 | E22: Medicaid Waiver | F22: CG-030 | G22: Hours | H22: 4.27 | I22: 0 | J22: =H22-I22 -> 4.27 | K22: 26.5 | L22: =J22*K22 -> 113.155 | M22: =H22*16.48*(1+'Chart of Accounts'!$E$67) -> 80.573192
B23: V-000018 | C23: 45658 | D23: CL-055 | E23: Private Pay | F23: CG-018 | G23: Hours | H23: 4.24 | I23: 0 | J23: =H23-I23 -> 4.24 | K23: 34 | L23: =J23*K23 -> 144.16 | M23: =H23*17.84*(1+'Chart of Accounts'!$E$67) -> 86.609632
B24: V-000019 | C24: 45658 | D24: CL-056 | E24: Medicare (Skilled) | F24: CG-009 | G24: Visits | H24: 0.95 | I24: 0 | J24: =H24-I24 -> 0.95 | K24: 165 | L24: =J24*K24 -> 156.75 | M24: =H24*49.43*(1+'Chart of Accounts'!$E$67) -> 53.767482
B25: V-000020 | C25: 45658 | D25: CL-057 | E25: Private Pay | F25: CG-028 | G25: Hours | H25: 4.14 | I25: 0 | J25: =H25-I25 -> 4.14 | K25: 34 | L25: =J25*K25 -> 140.76 | M25: =H25*17.99*(1+'Chart of Accounts'!$E$67) -> 85.277997
B26: V-000021 | C26: 45658 | D26: CL-059 | E26: Medicaid Waiver | F26: CG-038 | G26: Hours | H26: 3.56 | I26: 0 | J26: =H26-I26 -> 3.56 | K26: 26.5 | L26: =J26*K26 -> 94.34 | M26: =H26*16.02*(1+'Chart of Accounts'!$E$67) -> 65.300724
B27: V-000022 | C27: 45658 | D27: CL-060 | E27: Private Pay | F27: CG-034 | G27: Hours | H27: 4.03 | I27: 0 | J27: =H27-I27 -> 4.03 | K27: 34 | L27: =J27*K27 -> 137.02 | M27: =H27*17.1*(1+'Chart of Accounts'!$E$67) -> 78.905385
B28: V-000023 | C28: 45658 | D28: CL-064 | E28: Medicaid Waiver | F28: CG-014 | G28: Hours | H28: 3.44 | I28: 0 | J28: =H28-I28 -> 3.44 | K28: 26.5 | L28: =J28*K28 -> 91.16 | M28: =H28*15.67*(1+'Chart of Accounts'!$E$67) -> 61.720996
B29: V-000024 | C29: 45658 | D29: CL-065 | E29: Medicaid Waiver | F29: CG-001 | G29: Hours | H29: 5.01 | I29: 0 | J29: =H29-I29 -> 5.01 | K29: 26.5 | L29: =J29*K29 -> 132.765 | M29: =H29*14.56*(1+'Chart of Accounts'!$E$67) -> 83.522712
B30: V-000025 | C30: 45659 | D30: CL-004 | E30: Private Pay | F30: CG-004 | G30: Hours | H30: 3.86 | I30: 0 | J30: =H30-I30 -> 3.86 | K30: 34 | L30: =J30*K30 -> 131.24 | M30: =H30*16.05*(1+'Chart of Accounts'!$E$67) -> 70.936185
B31: V-000026 | C31: 45659 | D31: CL-008 | E31: Private Pay | F31: CG-008 | G31: Hours | H31: 3.23 | I31: 0 | J31: =H31-I31 -> 3.23 | K31: 34 | L31: =J31*K31 -> 109.82 | M31: =H31*15.19*(1+'Chart of Accounts'!$E$67) -> 56.177937
B32: V-000027 | C32: 45659 | D32: CL-015 | E32: Medicaid Waiver | F32: CG-006 | G32: Hours | H32: 2.95 | I32: 0 | J32: =H32-I32 -> 2.95 | K32: 26.5 | L32: =J32*K32 -> 78.175 | M32: =H32*15.05*(1+'Chart of Accounts'!$E$67) -> 50.835138
B33: V-000028 | C33: 45659 | D33: CL-016 | E33: Private Pay | F33: CG-002 | G33: Hours | H33: 4.2 | I33: 0 | J33: =H33-I33 -> 4.2 | K33: 34 | L33: =J33*K33 -> 142.8 | M33: =H33*17.34*(1+'Chart of Accounts'!$E$67) -> 83.38806
B34: V-000029 | C34: 45659 | D34: CL-018 | E34: Private Pay | F34: CG-011 | G34: Hours | H34: 2.83 | I34: 0 | J34: =H34-I34 -> 2.83 | K34: 34 | L34: =J34*K34 -> 96.22 | M34: =H34*16.65*(1+'Chart of Accounts'!$E$67) -> 53.951828
B35: V-000030 | C35: 45659 | D35: CL-020 | E35: Medicaid Waiver | F35: CG-016 | G35: Hours | H35: 3.63 | I35: 0 | J35: =H35-I35 -> 3.63 | K35: 26.5 | L35: =J35*K35 -> 96.195 | M35: =H35*16.19*(1+'Chart of Accounts'!$E$67) -> 67.291307
B36: V-000031 | C36: 45659 | D36: CL-022 | E36: Medicaid Waiver | F36: CG-013 | G36: Hours | H36: 3.2 | I36: 0 | J36: =H36-I36 -> 3.2 | K36: 26.5 | L36: =J36*K36 -> 84.8 | M36: =H36*16.71*(1+'Chart of Accounts'!$E$67) -> 61.22544
B37: V-000032 | C37: 45659 | D37: CL-024 | E37: Private Pay | F37: CG-017 | G37: Hours | H37: 3.98 | I37: 0 | J37: =H37-I37 -> 3.98 | K37: 34 | L37: =J37*K37 -> 135.32 | M37: =H37*16.43*(1+'Chart of Accounts'!$E$67) -> 74.873153
B38: V-000033 | C38: 45659 | D38: CL-025 | E38: Private Pay | F38: CG-019 | G38: Hours | H38: 3.97 | I38: 0 | J38: =H38-I38 -> 3.97 | K38: 34 | L38: =J38*K38 -> 134.98 | M38: =H38*14.93*(1+'Chart of Accounts'!$E$67) -> 67.866555
B39: V-000034 | C39: 45659 | D39: CL-028 | E39: Medicaid Waiver | F39: CG-023 | G39: Hours | H39: 3.06 | I39: 0 | J39: =H39-I39 -> 3.06 | K39: 26.5 | L39: =J39*K39 -> 81.09 | M39: =H39*16.17*(1+'Chart of Accounts'!$E$67) -> 56.654829
B40: V-000035 | C40: 45659 | D40: CL-030 | E40: Private Pay | F40: CG-018 | G40: Hours | H40: 3.17 | I40: 0 | J40: =H40-I40 -> 3.17 | K40: 34 | L40: =J40*K40 -> 107.78 | M40: =H40*17.84*(1+'Chart of Accounts'!$E$67) -> 64.752956
B41: V-000036 | C41: 45659 | D41: CL-031 | E41: Medicaid Waiver | F41: CG-038 | G41: Hours | H41: 4.06 | I41: 0 | J41: =H41-I41 -> 4.06 | K41: 26.5 | L41: =J41*K41 -> 107.59 | M41: =H41*16.02*(1+'Chart of Accounts'!$E$67) -> 74.472174
B42: V-000037 | C42: 45659 | D42: CL-039 | E42: Private Pay | F42: CG-013 | G42: Hours | H42: 4.33 | I42: 0 | J42: =H42-I42 -> 4.33 | K42: 34 | L42: =J42*K42 -> 147.22 | M42: =H42*16.71*(1+'Chart of Accounts'!$E$67) -> 82.845674
...

Sheet Daily Payroll Register
B2: Daily Payroll Register - Every Caregiver, Every Day, Full Year
B3: 5,973 payroll records. Source of truth for all direct labor cost across the workbook.
B5: Pay ID | C5: Date | D5: Caregiver ID | E5: Pay Type | F5: Reg Hours | G5: OT Hours | H5: Rate | I5: Reg Pay | J5: OT Pay | K5: Miles | L5: Mileage Pay | M5: Visits | N5: Per-Visit Pay | O5: Gross Pay
B6: P-000001 | C6: 45658 | D6: CG-003 | E6: Per Visit | H6: 66.48 | M6: 1 | N6: =M6*H6 -> 66.48 | O6: =N6 -> 66.48
B7: P-000002 | C7: 45658 | D7: CG-021 | E7: Per Visit | H7: 51.07 | M7: 1 | N7: =M7*H7 -> 51.07 | O7: =N7 -> 51.07
B8: P-000003 | C8: 45658 | D8: CG-004 | E8: Hourly | F8: 4.39 | G8: 0 | H8: 16.05 | I8: =F8*H8 -> 70.4595 | J8: =G8*H8*1.5 -> 0 | K8: 11.51 | L8: =K8*'Chart of Accounts'!$E$68 -> 7.7117 | O8: =I8+J8+L8 -> 78.1712
B9: P-000004 | C9: 45658 | D9: CG-005 | E9: Hourly | F9: 5.03 | G9: 0 | H9: 16 | I9: =F9*H9 -> 80.48 | J9: =G9*H9*1.5 -> 0 | K9: 11.77 | L9: =K9*'Chart of Accounts'!$E$68 -> 7.8859 | O9: =I9+J9+L9 -> 88.3659
B10: P-000005 | C10: 45658 | D10: CG-010 | E10: Hourly | F10: 4 | G10: 0 | H10: 16.36 | I10: =F10*H10 -> 65.44 | J10: =G10*H10*1.5 -> 0 | K10: 13.16 | L10: =K10*'Chart of Accounts'!$E$68 -> 8.8172 | O10: =I10+J10+L10 -> 74.2572
B11: P-000006 | C11: 45658 | D11: CG-033 | E11: Per Visit | H11: 57.54 | M11: 1 | N11: =M11*H11 -> 57.54 | O11: =N11 -> 57.54
B12: P-000007 | C12: 45658 | D12: CG-002 | E12: Hourly | F12: 3.81 | G12: 0 | H12: 17.34 | I12: =F12*H12 -> 66.0654 | J12: =G12*H12*1.5 -> 0 | K12: 9.87 | L12: =K12*'Chart of Accounts'!$E$68 -> 6.6129 | O12: =I12+J12+L12 -> 72.6783
B13: P-000008 | C13: 45658 | D13: CG-016 | E13: Hourly | F13: 4.21 | G13: 0 | H13: 16.19 | I13: =F13*H13 -> 68.1599 | J13: =G13*H13*1.5 -> 0 | K13: 12.19 | L13: =K13*'Chart of Accounts'!$E$68 -> 8.1673 | O13: =I13+J13+L13 -> 76.3272
B14: P-000009 | C14: 45658 | D14: CG-017 | E14: Hourly | F14: 3.82 | G14: 0 | H14: 16.43 | I14: =F14*H14 -> 62.7626 | J14: =G14*H14*1.5 -> 0 | K14: 8.83 | L14: =K14*'Chart of Accounts'!$E$68 -> 5.9161 | O14: =I14+J14+L14 -> 68.6787
B15: P-000010 | C15: 45658 | D15: CG-001 | E15: Hourly | F15: 8.83 | G15: 0 | H15: 14.56 | I15: =F15*H15 -> 128.5648 | J15: =G15*H15*1.5 -> 0 | K15: 24.15 | L15: =K15*'Chart of Accounts'!$E$68 -> 16.1805 | O15: =I15+J15+L15 -> 144.7453
B16: P-000011 | C16: 45658 | D16: CG-028 | E16: Hourly | F16: 7.23 | G16: 0 | H16: 17.99 | I16: =F16*H16 -> 130.0677 | J16: =G16*H16*1.5 -> 0 | K16: 17.27 | L16: =K16*'Chart of Accounts'!$E$68 -> 11.5709 | O16: =I16+J16+L16 -> 141.6386
B17: P-000012 | C17: 45658 | D17: CG-034 | E17: Hourly | F17: 7.5 | G17: 0 | H17: 17.1 | I17: =F17*H17 -> 128.25 | J17: =G17*H17*1.5 -> 0 | K17: 16.79 | L17: =K17*'Chart of Accounts'!$E$68 -> 11.2493 | O17: =I17+J17+L17 -> 139.4993
B18: P-000013 | C18: 45658 | D18: CG-008 | E18: Hourly | F18: 3.36 | G18: 0 | H18: 15.19 | I18: =F18*H18 -> 51.0384 | J18: =G18*H18*1.5 -> 0 | K18: 7.74 | L18: =K18*'Chart of Accounts'!$E$68 -> 5.1858 | O18: =I18+J18+L18 -> 56.2242
B19: P-000014 | C19: 45658 | D19: CG-011 | E19: Hourly | F19: 3.28 | G19: 0 | H19: 16.65 | I19: =F19*H19 -> 54.612 | J19: =G19*H19*1.5 -> 0 | K19: 10.26 | L19: =K19*'Chart of Accounts'!$E$68 -> 6.8742 | O19: =I19+J19+L19 -> 61.4862
B20: P-000015 | C20: 45658 | D20: CG-013 | E20: Hourly | F20: 4.16 | G20: 0 | H20: 16.71 | I20: =F20*H20 -> 69.5136 | J20: =G20*H20*1.5 -> 0 | K20: 10.57 | L20: =K20*'Chart of Accounts'!$E$68 -> 7.0819 | O20: =I20+J20+L20 -> 76.5955
B21: P-000016 | C21: 45658 | D21: CG-019 | E21: Hourly | F21: 4.48 | G21: 0 | H21: 14.93 | I21: =F21*H21 -> 66.8864 | J21: =G21*H21*1.5 -> 0 | K21: 11.38 | L21: =K21*'Chart of Accounts'!$E$68 -> 7.6246 | O21: =I21+J21+L21 -> 74.511
B22: P-000017 | C22: 45658 | D22: CG-030 | E22: Hourly | F22: 4.27 | G22: 0 | H22: 16.48 | I22: =F22*H22 -> 70.3696 | J22: =G22*H22*1.5 -> 0 | K22: 10.99 | L22: =K22*'Chart of Accounts'!$E$68 -> 7.3633 | O22: =I22+J22+L22 -> 77.7329
B23: P-000018 | C23: 45658 | D23: CG-018 | E23: Hourly | F23: 4.24 | G23: 0 | H23: 17.84 | I23: =F23*H23 -> 75.6416 | J23: =G23*H23*1.5 -> 0 | K23: 9.68 | L23: =K23*'Chart of Accounts'!$E$68 -> 6.4856 | O23: =I23+J23+L23 -> 82.1272
B24: P-000019 | C24: 45658 | D24: CG-009 | E24: Per Visit | H24: 49.43 | M24: 1 | N24: =M24*H24 -> 49.43 | O24: =N24 -> 49.43
B25: P-000020 | C25: 45658 | D25: CG-038 | E25: Hourly | F25: 3.56 | G25: 0 | H25: 16.02 | I25: =F25*H25 -> 57.0312 | J25: =G25*H25*1.5 -> 0 | K25: 8.32 | L25: =K25*'Chart of Accounts'!$E$68 -> 5.5744 | O25: =I25+J25+L25 -> 62.6056
B26: P-000021 | C26: 45658 | D26: CG-014 | E26: Hourly | F26: 3.44 | G26: 0 | H26: 15.67 | I26: =F26*H26 -> 53.9048 | J26: =G26*H26*1.5 -> 0 | K26: 8.46 | L26: =K26*'Chart of Accounts'!$E$68 -> 5.6682 | O26: =I26+J26+L26 -> 59.573
B27: P-000022 | C27: 45659 | D27: CG-004 | E27: Hourly | F27: 3.86 | G27: 0 | H27: 16.05 | I27: =F27*H27 -> 61.953 | J27: =G27*H27*1.5 -> 0 | K27: 9.41 | L27: =K27*'Chart of Accounts'!$E$68 -> 6.3047 | O27: =I27+J27+L27 -> 68.2577
B28: P-000023 | C28: 45659 | D28: CG-008 | E28: Hourly | F28: 3.23 | G28: 0 | H28: 15.19 | I28: =F28*H28 -> 49.0637 | J28: =G28*H28*1.5 -> 0 | K28: 8.04 | L28: =K28*'Chart of Accounts'!$E$68 -> 5.3868 | O28: =I28+J28+L28 -> 54.4505
B29: P-000024 | C29: 45659 | D29: CG-006 | E29: Hourly | F29: 5.8 | G29: 0 | H29: 15.05 | I29: =F29*H29 -> 87.29 | J29: =G29*H29*1.5 -> 0 | K29: 15.92 | L29: =K29*'Chart of Accounts'!$E$68 -> 10.6664 | O29: =I29+J29+L29 -> 97.9564
B30: P-000025 | C30: 45659 | D30: CG-002 | E30: Hourly | F30: 4.2 | G30: 0 | H30: 17.34 | I30: =F30*H30 -> 72.828 | J30: =G30*H30*1.5 -> 0 | K30: 10.39 | L30: =K30*'Chart of Accounts'!$E$68 -> 6.9613 | O30: =I30+J30+L30 -> 79.7893
B31: P-000026 | C31: 45659 | D31: CG-011 | E31: Hourly | F31: 2.83 | G31: 0 | H31: 16.65 | I31: =F31*H31 -> 47.1195 | J31: =G31*H31*1.5 -> 0 | K31: 8.24 | L31: =K31*'Chart of Accounts'!$E$68 -> 5.5208 | O31: =I31+J31+L31 -> 52.6403
B32: P-000027 | C32: 45659 | D32: CG-016 | E32: Hourly | F32: 3.63 | G32: 0 | H32: 16.19 | I32: =F32*H32 -> 58.7697 | J32: =G32*H32*1.5 -> 0 | K32: 12.45 | L32: =K32*'Chart of Accounts'!$E$68 -> 8.3415 | O32: =I32+J32+L32 -> 67.1112
B33: P-000028 | C33: 45659 | D33: CG-013 | E33: Hourly | F33: 7.53 | G33: 0 | H33: 16.71 | I33: =F33*H33 -> 125.8263 | J33: =G33*H33*1.5 -> 0 | K33: 20.73 | L33: =K33*'Chart of Accounts'!$E$68 -> 13.8891 | O33: =I33+J33+L33 -> 139.7154
B34: P-000029 | C34: 45659 | D34: CG-017 | E34: Hourly | F34: 3.98 | G34: 0 | H34: 16.43 | I34: =F34*H34 -> 65.3914 | J34: =G34*H34*1.5 -> 0 | K34: 10.38 | L34: =K34*'Chart of Accounts'!$E$68 -> 6.9546 | O34: =I34+J34+L34 -> 72.346
B35: P-000030 | C35: 45659 | D35: CG-019 | E35: Hourly | F35: 3.97 | G35: 0 | H35: 14.93 | I35: =F35*H35 -> 59.2721 | J35: =G35*H35*1.5 -> 0 | K35: 13.78 | L35: =K35*'Chart of Accounts'!$E$68 -> 9.2326 | O35: =I35+J35+L35 -> 68.5047
B36: P-000031 | C36: 45659 | D36: CG-023 | E36: Hourly | F36: 3.06 | G36: 0 | H36: 16.17 | I36: =F36*H36 -> 49.4802 | J36: =G36*H36*1.5 -> 0 | K36: 6.93 | L36: =K36*'Chart of Accounts'!$E$68 -> 4.6431 | O36: =I36+J36+L36 -> 54.1233
... B42: P-000037 | C42: 45659 | D42: CG-034 | E42: Hourly | F42: 3.95 | G42: 0 | H42: 17.1 | I42: =F42*H42 -> 67.545 | J42: =G42*H42*1.5 -> 0 | K42: 11.7 | L42: =K42*'Chart of Accounts'!$E$68 -> 7.839 | O42: =I42+J42+L42 -> 75.384
B43: P-000038 | C43: 45660 | D43: CG-003 | E43: Per Visit | H43: 66.48 | M43: 1 | N43: =M43*H43 -> 66.48 | O43: =N43 -> 66.48
B44: P-000039 | C44: 45660 | D44: CG-004 | E44: Hourly | F44: 4.02 | G44: 0 | H44: 16.05 | I44: =F44*H44 -> 64.521 | J44: =G44*H44*1.5 -> 0 | K44: 13.21 | L44: =K44*'Chart of Accounts'!$E$68 -> 8.8507 | O44: =I44+J44+L44 -> 73.3717
B45: P-000040 | C45: 45660 | D45: CG-005 | E45: Hourly | F45: 5.06 | G45: 0 | H45: 16 | I45: =F45*H45 -> 80.96 | J45: =G45*H45*1.5 -> 0 | K45: 13.8 | L45: =K45*'Chart of Accounts'!$E$68 -> 9.246 | O45: =I45+J45+L45 -> 90.206
B46: P-000041 | C46: 45660 | D46: CG-012 | E46: Per Visit | H46: 73.58 | M46: 2 | N46: =M46*H46 -> 147.16 | O46: =N46 -> 147.16
B47: P-000042 | C47: 45660 | D47: CG-010 | E47: Hourly | F47: 3.8 | G47: 0 | H47: 16.36 | I47: =F47*H47 -> 62.168 | J47: =G47*H47*1.5 -> 0 | K47: 12.3 | L47: =K47*'Chart of Accounts'!$E$68 -> 8.241 | O47: =I47+J47+L47 -> 70.409
...

Sheet Missed Visits Log
B2: Missed Visits Log
B3: Uncovered or cancelled visits and the revenue lost - an operational KPI, not just a billing gap.
B5: Date | C5: Client ID | D5: Payer | E5: Reason | F5: Lost Units | G5: Lost Revenue
B6: 45658 | C6: CL-045 | D6: Medicaid Waiver | E6: Client cancelled same-day | F6: 4.56 | G6: 120.84
B7: 45672 | C7: CL-054 | D7: Medicaid Waiver | E7: Client cancelled same-day | F7: 4.01 | G7: 106.27
B8: 45681 | C8: CL-024 | D8: Private Pay | E8: Weather/transportation issue | F8: 4.3 | G8: 146.2
B9: 45687 | C9: CL-024 | D9: Private Pay | E9: Caregiver call-off, no replacement found | F9: 4.28 | G9: 145.52
B10: 45690 | C10: CL-055 | D10: Private Pay | E10: Client cancelled same-day | F10: 3.94 | G10: 133.96
B11: 45691 | C11: CL-016 | D11: Private Pay | E11: Client cancelled same-day | F11: 4.17 | G11: 141.78
B12: 45694 | C12: CL-004 | D12: Private Pay | E12: Client cancelled same-day | F12: 4.16 | G12: 141.44
B13: 45694 | C13: CL-015 | D13: Medicaid Waiver | E13: Client cancelled same-day | F13: 2.97 | G13: 78.7
B14: 45695 | C14: CL-014 | D14: Private Insurance | E14: Caregiver call-off, no replacement found | F14: 1.05 | G14: 141.75
B15: 45695 | C15: CL-040 | D15: Medicare (Skilled) | E15: Client cancelled same-day | F15: 0.93 | G15: 153.45
B16: 45697 | C16: CL-039 | D16: Private Pay | E16: Caregiver call-off, no replacement found | F16: 4.04 | G16: 137.36
B17: 45698 | C17: CL-004 | D17: Private Pay | E17: Weather/transportation issue | F17: 4.35 | G17: 147.9
... B212: 46020 | C212: CL-064 | D212: Medicaid Waiver | E212: Caregiver call-off, no replacement found | F212: 3 | G212: 79.5
B214: TOTAL LOST REVENUE (Year) | G214: =SUM(G6:G212) -> 25605.39
B215: Total Missed Visit Events | C215: =COUNTA(B6:B212) -> 207

Sheet Payroll Summary
B2: Payroll Summary - Monthly Rollup
B3: Aggregated from Daily Payroll Register via date-range SUMIFS. Employer burden applied to gross wages.
C5: Jan-2025 | D5: Feb-2025 | E5: Mar-2025 | F5: Apr-2025 | G5: May-2025 | H5: Jun-2025 | I5: Jul-2025 | J5: Aug-2025 | K5: Sep-2025 | L5: Oct-2025 | M5: Nov-2025 | N5: Dec-2025 | O5: FY Total
B6: Regular Wages (Hourly) | C6: =SUMIFS('Daily Payroll Register'!$I$6:$I$5978,'Daily Payroll Register'!$C$6:$C$5978,">="&DATE(2025,1,1),'Daily Payroll Register'!$C$6:$C$5978,"<"&DATE(2025,2,1)) -> 32619.694 | D6: =SUMIFS('Daily Payroll Register'!$I$6:$I$5978,'Daily Payroll Register'!$C$6:$C$5978,">="&DATE(2025,2,1),'Daily Payroll Register'!$C$6:$C$5978,"<"&DATE(2025,3,1)) -> 28107.475 | E6: =SUMIFS('Daily Payroll Register'!$I$6:$I$5978,'Daily Payroll Register'!$C$6:$C$5978,">="&DATE(2025,3,1),'Daily Payroll Register'!$C$6:$C$5978,"<"&DATE(2025,4,1)) -> 30891.1 | F6: =SUMIFS('Daily Payroll Register'!$I$6:$I$5978,'Daily Payroll Register'!$C$6:$C$5978,">="&DATE(2025,4,1),'Daily Payroll Register'!$C$6:$C$5978,"<"&DATE(2025,5,1)) -> 31877.566 | G6: =SUMIFS('Daily Payroll Register'!$I$6:$I$5978,'Daily Payroll Register'!$C$6:$C$5978,">="&DATE(2025,5,1),'Daily Payroll Register'!$C$6:$C$5978,"<"&DATE(2025,6,1)) -> 33491.019 | H6: =SUMIFS('Daily Payroll Register'!$I$6:$I$5978,'Daily Payroll Register'!$C$6:$C$5978,">="&DATE(2025,6,1),'Daily Payroll Register'!$C$6:$C$5978,"<"&DATE(2025,7,1)) -> 33038.073 | I6: =SUMIFS('Daily Payroll Register'!$I$6:$I$5978,'Daily Payroll Register'!$C$6:$C$5978,">="&DATE(2025,7,1),'Daily Payroll Register'!$C$6:$C$5978,"<"&DATE(2025,8,1)) -> 34800.117 | J6: =SUMIFS('Daily Payroll Register'!$I$6:$I$5978,'Daily Payroll Register'!$C$6:$C$5978,">="&DATE(2025,8,1),'Daily Payroll Register'!$C$6:$C$5978,"<"&DATE(2025,9,1)) -> 36518.632 | K6: =SUMIFS('Daily Payroll Register'!$I$6:$I$5978,'Daily Payroll Register'!$C$6:$C$5978,">="&DATE(2025,9,1),'Daily Payroll Register'!$C$6:$C$5978,"<"&DATE(2025,10,1)) -> 36743.121 | L6: =SUMIFS('Daily Payroll Register'!$I$6:$I$5978,'Daily Payroll Register'!$C$6:$C$5978,">="&DATE(2025,10,1),'Daily Payroll Register'!$C$6:$C$5978,"<"&DATE(2025,11,1)) -> 40819.497 | M6: =SUMIFS('Daily Payroll Register'!$I$6:$I$5978,'Daily Payroll Register'!$C$6:$C$5978,">="&DATE(2025,11,1),'Daily Payroll Register'!$C$6:$C$5978,"<"&DATE(2025,12,1)) -> 37196.333 | N6: =SUMIFS('Daily Payroll Register'!$I$6:$I$5978,'Daily Payroll Register'!$C$6:$C$5978,">="&DATE(2025,12,1),'Daily Payroll Register'!$C$6:$C$5978,"<"&DATE(2026,1,1)) -> 40241.366 | O6: =SUM(C6:N6) -> 416343.99
B7: Overtime Wages (Hourly) | C7: =SUMIFS('Daily Payroll Register'!$J$6:$J$5978,'Daily Payroll Register'!$C$6:$C$5978,">="&DATE(2025,1,1),'Daily Payroll Register'!$C$6:$C$5978,"<"&DATE(2025,2,1)) -> 0 | D7: =SUMIFS('Daily Payroll Register'!$J$6:$J$5978,'Daily Payroll Register'!$C$6:$C$5978,">="&DATE(2025,2,1),'Daily Payroll Register'!$C$6:$C$5978,"<"&DATE(2025,3,1)) -> 0 | E7: =SUMIFS('Daily Payroll Register'!$J$6:$J$5978,'Daily Payroll Register'!$C$6:$C$5978,">="&DATE(2025,3,1),'Daily Payroll Register'!$C$6:$C$5978,"<"&DATE(2025,4,1)) -> 0 | F7: =SUMIFS('Daily Payroll Register'!$J$6:$J$5978,'Daily Payroll Register'!$C$6:$C$5978,">="&DATE(2025,4,1),'Daily Payroll Register'!$C$6:$C$5978,"<"&DATE(2025,5,1)) -> 0 | G7: =SUMIFS('Daily Payroll Register'!$J$6:$J$5978,'Daily Payroll Register'!$C$6:$C$5978,">="&DATE(2025,5,1),'Daily Payroll Register'!$C$6:$C$5978,"<"&DATE(2025,6,1)) -> 36.240855 | H7: =SUMIFS('Daily Payroll Register'!$J$6:$J$5978,'Daily Payroll Register'!$C$6:$C$5978,">="&DATE(2025,6,1),'Daily Payroll Register'!$C$6:$C$5978,"<"&DATE(2025,7,1)) -> 140.17293 | I7: =SUMIFS('Daily Payroll Register'!$J$6:$J$5978,'Daily Payroll Register'!$C$6:$C$5978,">="&DATE(2025,7,1),'Daily Payroll Register'!$C$6:$C$5978,"<"&DATE(2025,8,1)) -> 505.92061 | J7: =SUMIFS('Daily Payroll Register'!$J$6:$J$5978,'Daily Payroll Register'!$C$6:$C$5978,">="&DATE(2025,8,1),'Daily Payroll Register'!$C$6:$C$5978,"<"&DATE(2025,9,1)) -> 1027.6718 | K7: =SUMIFS('Daily Payroll Register'!$J$6:$J$5978,'Daily Payroll Register'!$C$6:$C$5978,">="&DATE(2025,9,1),'Daily Payroll Register'!$C$6:$C$5978,"<"&DATE(2025,10,1)) -> 1573.3105 | L7: =SUMIFS('Daily Payroll Register'!$J$6:$J$5978,'Daily Payroll Register'!$C$6:$C$5978,">="&DATE(2025,10,1),'Daily Payroll Register'!$C$6:$C$5978,"<"&DATE(2025,11,1)) -> 734.2698 | M7: =SUMIFS('Daily Payroll Register'!$J$6:$J$5978,'Daily Payroll Register'!$C$6:$C$5978,">="&DATE(2025,11,1),'Daily Payroll Register'!$C$6:$C$5978,"<"&DATE(2025,12,1)) -> 879.38878 | N7: =SUMIFS('Daily Payroll Register'!$J$6:$J$5978,'Daily Payroll Register'!$C$6:$C$5978,">="&DATE(2025,12,1),'Daily Payroll Register'!$C$6:$C$5978,"<"&DATE(2026,1,1)) -> 1062.9302 | O7: =SUM(C7:N7) -> 5959.9054
B8: Mileage Reimbursement | C8: =SUMIFS('Daily Payroll Register'!$L$6:$L$5978,'Daily Payroll Register'!$C$6:$C$5978,">="&DATE(2025,1,1),'Daily Payroll Register'!$C$6:$C$5978,"<"&DATE(2025,2,1)) -> 3883.9833 | D8: =SUMIFS('Daily Payroll Register'!$L$6:$L$5978,'Daily Payroll Register'!$C$6:$C$5978,">="&DATE(2025,2,1),'Daily Payroll Register'!$C$6:$C$5978,"<"&DATE(2025,3,1)) -> 3341.089 | E8: =SUMIFS('Daily Payroll Register'!$L$6:$L$5978,'Daily Payroll Register'!$C$6:$C$5978,">="&DATE(2025,3,1),'Daily Payroll Register'!$C$6:$C$5978,"<"&DATE(2025,4,1)) -> 3648.6726 | F8: =SUMIFS('Daily Payroll Register'!$L$6:$L$5978,'Daily Payroll Register'!$C$6:$C$5978,">="&DATE(2025,4,1),'Daily Payroll Register'!$C$6:$C$5978,"<"&DATE(2025,5,1)) -> 3732.3958 | G8: =SUMIFS('Daily Payroll Register'!$L$6:$L$5978,'Daily Payroll Register'!$C$6:$C$5978,">="&DATE(2025,5,1),'Daily Payroll Register'!$C$6:$C$5978,"<"&DATE(2025,6,1)) -> 3998.3724 | H8: =SUMIFS('Daily Payroll Register'!$L$6:$L$5978,'Daily Payroll Register'!$C$6:$C$5978,">="&DATE(2025,6,1),'Daily Payroll Register'!$C$6:$C$5978,"<"&DATE(2025,7,1)) -> 3872.2717 | I8: =SUMIFS('Daily Payroll Register'!$L$6:$L$5978,'Daily Payroll Register'!$C$6:$C$5978,">="&DATE(2025,7,1),'Daily Payroll Register'!$C$6:$C$5978,"<"&DATE(2025,8,1)) -> 4171.0515 | J8: =SUMIFS('Daily Payroll Register'!$L$6:$L$5978,'Daily Payroll Register'!$C$6:$C$5978,">="&DATE(2025,8,1),'Daily Payroll Register'!$C$6:$C$5978,"<"&DATE(2025,9,1)) -> 4414.7104 | K8: =SUMIFS('Daily Payroll Register'!$L$6:$L$5978,'Daily Payroll Register'!$C$6:$C$5978,">="&DATE(2025,9,1),'Daily Payroll Register'!$C$6:$C$5978,"<"&DATE(2025,10,1)) -> 4562.365 | L8: =SUMIFS('Daily Payroll Register'!$L$6:$L$5978,'Daily Payroll Register'!$C$6:$C$5978,">="&DATE(2025,10,1),'Daily Payroll Register'!$C$6:$C$5978,"<"&DATE(2025,11,1)) -> 4933.4646 | M8: =SUMIFS('Daily Payroll Register'!$L$6:$L$5978,'Daily Payroll Register'!$C$6:$C$5978,">="&DATE(2025,11,1),'Daily Payroll Register'!$C$6:$C$5978,"<"&DATE(2025,12,1)) -> 4502.1722 | N8: =SUMIFS('Daily Payroll Register'!$L$6:$L$5978,'Daily Payroll Register'!$C$6:$C$5978,">="&DATE(2025,12,1),'Daily Payroll Register'!$C$6:$C$5978,"<"&DATE(2026,1,1)) -> 4834.4855 | O8: =SUM(C8:N8) -> 49895.034
B9: Per-Visit Pay (Skilled) | C9: =SUMIFS('Daily Payroll Register'!$N$6:$N$5978,'Daily Payroll Register'!$C$6:$C$5978,">="&DATE(2025,1,1),'Daily Payroll Register'!$C$6:$C$5978,"<"&DATE(2025,2,1)) -> 7029.21 | D9: =SUMIFS('Daily Payroll Register'!$N$6:$N$5978,'Daily Payroll Register'!$C$6:$C$5978,">="&DATE(2025,2,1),'Daily Payroll Register'!$C$6:$C$5978,"<"&DATE(2025,3,1)) -> 6264.43 | E9: =SUMIFS('Daily Payroll Register'!$N$6:$N$5978,'Daily Payroll Register'!$C$6:$C$5978,">="&DATE(2025,3,1),'Daily Payroll Register'!$C$6:$C$5978,"<"&DATE(2025,4,1)) -> 6667.57 | F9: =SUMIFS('Daily Payroll Register'!$N$6:$N$5978,'Daily Payroll Register'!$C$6:$C$5978,">="&DATE(2025,4,1),'Daily Payroll Register'!$C$6:$C$5978,"<"&DATE(2025,5,1)) -> 7998.63 | G9: =SUMIFS('Daily Payroll Register'!$N$6:$N$5978,'Daily Payroll Register'!$C$6:$C$5978,">="&DATE(2025,5,1),'Daily Payroll Register'!$C$6:$C$5978,"<"&DATE(2025,6,1)) -> 7517.88 | H9: =SUMIFS('Daily Payroll Register'!$N$6:$N$5978,'Daily Payroll Register'!$C$6:$C$5978,">="&DATE(2025,6,1),'Daily Payroll Register'!$C$6:$C$5978,"<"&DATE(2025,7,1)) -> 6958.45 | I9: =SUMIFS('Daily Payroll Register'!$N$6:$N$5978,'Daily Payroll Register'!$C$6:$C$5978,">="&DATE(2025,7,1),'Daily Payroll Register'!$C$6:$C$5978,"<"&DATE(2025,8,1)) -> 7887.95 | J9: =SUMIFS('Daily Payroll Register'!$N$6:$N$5978,'Daily Payroll Register'!$C$6:$C$5978,">="&DATE(2025,8,1),'Daily Payroll Register'!$C$6:$C$5978,"<"&DATE(2025,9,1)) -> 9050.45 | K9: =SUMIFS('Daily Payroll Register'!$N$6:$N$5978,'Daily Payroll Register'!$C$6:$C$5978,">="&DATE(2025,9,1),'Daily Payroll Register'!$C$6:$C$5978,"<"&DATE(2025,10,1)) -> 8731.54 | L9: =SUMIFS('Daily Payroll Register'!$N$6:$N$5978,'Daily Payroll Register'!$C$6:$C$5978,">="&DATE(2025,10,1),'Daily Payroll Register'!$C$6:$C$5978,"<"&DATE(2025,11,1)) -> 9218.36 | M9: =SUMIFS('Daily Payroll Register'!$N$6:$N$5978,'Daily Payroll Register'!$C$6:$C$5978,">="&DATE(2025,11,1),'Daily Payroll Register'!$C$6:$C$5978,"<"&DATE(2025,12,1)) -> 7880.77 | N9: =SUMIFS('Daily Payroll Register'!$N$6:$N$5978,'Daily Payroll Register'!$C$6:$C$5978,">="&DATE(2025,12,1),'Daily Payroll Register'!$C$6:$C$5978,"<"&DATE(2026,1,1)) -> 9517.01 | O9: =SUM(C9:N9) -> 94722.25
B10: Gross Payroll (Subtotal) | C10: =SUM(C6:C9) -> 43532.887 | D10: =SUM(D6:D9) -> 37712.994 | E10: =SUM(E6:E9) -> 41207.343 | F10: =SUM(F6:F9) -> 43608.592 | G10: =SUM(G6:G9) -> 45043.512 | H10: =SUM(H6:H9) -> 44008.968 | I10: =SUM(I6:I9) -> 47365.04 | J10: =SUM(J6:J9) -> 51011.464 | ... N10: =SUM(N6:N9) -> 55655.791 | O10: =SUM(C10:N10) -> 566921.18
B11: Payroll Tax & Burden (Employer) | C11: =C10*'Chart of Accounts'!$E$67 -> 6312.2686 | D11: =D10*'Chart of Accounts'!$E$67 -> 5468.3841 | E11: =E10*'Chart of Accounts'!$E$67 -> 5975.0647 | F11: =F10*'Chart of Accounts'!$E$67 -> 6323.2458 | G11: =G10*'Chart of Accounts'!$E$67 -> 6531.3093 | H11: =H10*'Chart of Accounts'!$E$67 -> 6381.3004 | I11: =I10*'Chart of Accounts'!$E$67 -> 6867.9307 | J11: =J10*'Chart of Accounts'!$E$67 -> 7396.6622 | ... N11: =N10*'Chart of Accounts'!$E$67 -> 8070.0898 | O11: =SUM(C11:N11) -> 82203.571
B12: TOTAL FULLY-LOADED PAYROLL | C12: =C10+C11 -> 49845.156 | D12: =D10+D11 -> 43181.378 | E12: =E10+E11 -> 47182.407 | F12: =F10+F11 -> 49931.838 | G12: =G10+G11 -> 51574.821 | H12: =H10+H11 -> 50390.268 | I12: =I10+I11 -> 54232.97 | J12: =J10+J11 -> 58408.126 | ... N12: =N10+N11 -> 63725.881 | O12: =SUM(C12:N12) -> 649124.75

Sheet Revenue by Payer
B2: Revenue Summary by Payer - Monthly
B3: Net billed revenue by payer, rolled up from the Daily Visit Register via date-range SUMIFS.
C5: Jan-2025 | D5: Feb-2025 | E5: Mar-2025 | F5: Apr-2025 | G5: May-2025 | H5: Jun-2025 | I5: Jul-2025 | J5: Aug-2025 | K5: Sep-2025 | L5: Oct-2025 | M5: Nov-2025 | N5: Dec-2025 | O5: FY Total
